<?xml version="1.0"?>
<!-- Revolute-Revolute Manipulator -->
<robot name="fullGoatLeg" xmlns:xacro="http://ros.org/wiki/xacro">

  <!-- Constants for robot dimensions -->
  <xacro:property name="PI" value="3.1415926535897931"/>

  <!-- Import all Gazebo-customization elements, including Gazebo colors -->
  <!-- <xacro:include filename="$(find rrbot_description)/urdf/rrbot.gazebo" /> -->
  <!-- Import Rviz colors -->
	<xacro:include filename="$(find rrbot_description)/urdf/openGoatLeg.xacro" />

	<link name="world" />

	<joint name="world_joint" type="fixed">
		<parent link="world" />
		<child link = "hipJoint" />
		<origin xyz="0.0 0.0 1" rpy="0.0 0.0 0.0" />
	</joint>

	<link name="footAssembly">
		<visual>
			<geometry>
				<mesh filename="package://rrbot_description/meshes/footassembly.dae"/>
			</geometry>
			<origin xyz="0 0 0" rpy="0 0 ${PI}"/>
		</visual>
		<collision>
			<geometry>
				<mesh filename="package://rrbot_description/meshes/footassembly.dae"/>
			</geometry>
			<origin xyz="0 0 0" rpy="0 0 ${PI}"/>
		</collision>
		<inertial>
			<mass value="0.02883033104"/>
			<inertia ixx="0.00757" ixy="0.0" ixz="0.0" iyy="0.212" iyz="0.0" izz="0.21199"/>
		</inertial>
  	</link>

  	<joint name="footBracket_to_footAssembly" type="revolute">
		<axis xyz="0 0 1"/>
		<limit effort="1000.0" lower="${-PI}" upper="${PI}" velocity="0"/>
		<origin xyz="0 0.01159 0" rpy="0 0 0"/>
		<parent link="leg1_footBracket"/>
		<child link="leg2_footBracket"/>
  	</joint>

</robot>